Workbook

Sheet Instructions
B2: Meridian — Sample Workbook
B4: This is a SAMPLE built from synthetic data (not real reported financials or prices) so you can evaluate the calculation logic before we connect real data.
B6: How it's structured:
B8: • 'Company Master', 'Fundamentals Raw' and 'Price History' / 'Benchmark Price History' are INPUT sheets (yellow-filled cells) — this is where you paste real exports from your data source.
B9: • 'Screener' is the OUTPUT sheet — every cell there is a live formula pulling from the input sheets. Change an input and the Screener sheet recalculates.
B10: • Fundamentals Raw needs the last 4 fiscal years per stock, one row each, so the sheet can compute a trailing 3-year average and isolate the latest year.
B11: • Price History needs one row per stock per trading day (Close + Volume). More history = more reliable 200-day MA and 52-week range. ~260 trading days (~1yr) is the practical minimum.
B12: • Benchmark Price History is optional — only needed for the Relative Strength column.
B13: • Improvement / Deterioration flags use a ±3% variation band as the neutral zone — last year's value has to move more than 3% away from the trailing 3-year average to count as a real shift. Debt/Equity's flag direction is inverted (lower is better).

Sheet Screener
A1: ISIN | B1: Name | C1: Sector | D1: CMP | E1: 1D Chg | F1: 1D Chg% | G1: MarketCap | H1: PE | I1: Vol Breakout % | J1: 52w High | K1: 52w Low | L1: Vol Today | M1: Vol 30d Avg | N1: MA3 | O1: MA8 | P1: MA30 | Q1: MA50 | R1: MA100 | S1: MA200 | T1: RSI14 | U1: RS Rating | V1: S3 | W1: S8 | X1: S30 | Y1: S50 | Z1: S100 | AA1: S200 | AB1: M3 | AC1: M8 | AD1: M30 | AE1: M100 | AF1: ROE 3yr avg | AG1: ROE LY | AH1: ROE Var% | AI1: ROE Flag | AJ1: ROCE 3yr avg | AK1: ROCE LY | AL1: ROCE Var% | AM1: ROCE Flag | AN1: EPS Gr 3yr avg | AO1: EPS Gr LY | AP1: EPS Gr Var% | AQ1: EPS Gr Flag | AR1: Sales Gr 3yr avg | AS1: Sales Gr LY | AT1: Sales Gr Var% | AU1: Sales Gr Flag | AV1: D/E 3yr avg | AW1: D/E LY | AX1: D/E Var% | AY1: D/E Flag | AZ1: AssetTurns 3yr avg | BA1: AssetTurns LY | BB1: AssetTurns Var% | BC1: AssetTurns Flag | BD1: CWIP % of FA | BE1: % from 52w High | BF1: % from 52w Low | BG1: CMP/52w Low | BH1: FundRow | BI1: RS RawScore | BJ1: RS Band | BK1: MA200 Slope% | BL1: MA200 Rising | BM1: FinExempt | BN1: Pctl ROCE | BO1: Pctl ROE | BP1: Pctl EPSg | BQ1: Pctl Salesg | BR1: Pctl DE | BS1: Pctl AssetTurn | BT1: Pctl Capex | BU1: Fund Score | BV1: Fund Tier
A2: ='Company Master'!A2 -> INE002A01018 | B2: ='Company Master'!C2 -> Reliance Industries | C2: ='Company Master'!D2 -> Energy | D2: =SUMPRODUCT(('Price History'!$A$2:$A$1561=A2)*('Price History'!$E$2:$E$1561=1)*'Price History'!$C$2:$C$1561) -> 2889.58 | E2: =D2-(SUMPRODUCT(('Price History'!$A$2:$A$1561=A2)*('Price History'!$E$2:$E$1561=2)*'Price History'!$C$2:$C$1561)) -> 5.99 | F2: =IFERROR(E2/(SUMPRODUCT(('Price History'!$A$2:$A$1561=A2)*('Price History'!$E$2:$E$1561=2)*'Price History'!$C$2:$C$1561)),"") -> 0.0020772717 | G2: ='Company Master'!E2 -> 1750000 | H2: =IFERROR(D2/(INDEX('Fundamentals Raw'!$A:$AG,BH2,13)),'Company Master'!F2) -> 48.523594 | I2: =IFERROR(L2/M2*100,"") -> 116.44473 | J2: =_xlfn.MAXIFS('Price History'!$C$2:$C$1561,'Price History'!$A$2:$A$1561,A2,'Price History'!$E$2:$E$1561,"<=252") -> 2889.58 | K2: =_xlfn.MINIFS('Price History'!$C$2:$C$1561,'Price History'!$A$2:$A$1561,A2,'Price History'!$E$2:$E$1561,"<=252") -> 2356.78 | L2: =SUMPRODUCT(('Price History'!$A$2:$A$1561=A2)*('Price History'!$E$2:$E$1561=1)*'Price History'!$D$2:$D$1561) -> 1769569 | M2: =AVERAGEIFS('Price History'!$D$2:$D$1561,'Price History'!$A$2:$A$1561,A2,'Price History'!$E$2:$E$1561,"<=30") -> 1519664.3 | N2: =IFERROR(AVERAGEIFS('Price History'!$C$2:$C$1561,'Price History'!$A$2:$A$1561,A2,'Price History'!$E$2:$E$1561,"<=3"),"") -> 2877.93 | O2: =IFERROR(AVERAGEIFS('Price History'!$C$2:$C$1561,'Price History'!$A$2:$A$1561,A2,'Price History'!$E$2:$E$1561,"<=8"),"") -> 2865.8362 | P2: =IFERROR(AVERAGEIFS('Price History'!$C$2:$C$1561,'Price History'!$A$2:$A$1561,A2,'Price History'!$E$2:$E$1561,"<=30"),"") -> 2838.283 | Q2: =IFERROR(AVERAGEIFS('Price History'!$C$2:$C$1561,'Price History'!$A$2:$A$1561,A2,'Price History'!$E$2:$E$1561,"<=50"),"") -> 2797.5716 | R2: =IFERROR(AVERAGEIFS('Price History'!$C$2:$C$1561,'Price History'!$A$2:$A$1561,A2,'Price History'!$E$2:$E$1561,"<=100"),"") -> 2730.7821 | S2: =IFERROR(AVERAGEIFS('Price History'!$C$2:$C$1561,'Price History'!$A$2:$A$1561,A2,'Price History'!$E$2:$E$1561,"<=200"),"") -> 2663.2487 | T2: =IFERROR(100-100/(1+(AVERAGEIFS('Price History'!$G$2:$G$1561,'Price History'!$A$2:$A$1561,A2,'Price History'!$E$2:$E$1561,"<=14"))/(AVERAGEIFS('Price History'!$H$2:$H$1561,'Price History'!$A$2:$A$1561,A2,'Price History'!$E$2:$E$1561,"<=14"))),100) -> 59.6126 | U2: =IFERROR(ROUND(1+98*(RANK(BI2,$BI$2:$BI$7,1)-1)/(COUNT($BI$2:$BI$7)-1),0),"") -> 79 | V2: =IF(N2="","",D2>N2) -> TRUE | W2: =IF(O2="","",D2>O2) -> TRUE | X2: =IF(P2="","",D2>P2) -> TRUE | Y2: =IF(Q2="","",D2>Q2) -> TRUE | Z2: =IF(R2="","",D2>R2) -> TRUE | AA2: =IF(S2="","",D2>S2) -> TRUE | AB2: =IF(OR(N2="",O2=""),"",N2>O2) -> TRUE | AC2: =IF(OR(O2="",P2=""),"",O2>P2) -> TRUE | AD2: =IF(OR(P2="",R2=""),"",P2>R2) -> TRUE | AE2: =IF(OR(R2="",S2=""),"",R2>S2) -> TRUE | AF2: =IFERROR(AVERAGE(INDEX('Fundamentals Raw'!$A:$AG,BH2,3),INDEX('Fundamentals Raw'!$A:$AG,BH2,4),INDEX('Fundamentals Raw'!$A:$AG,BH2,5)),"") -> 16.086667 | AG2: =IFERROR(INDEX('Fundamentals Raw'!$A:$AG,BH2,5),"") -> 18.46 | AH2: =IFERROR((AG2-AF2)/ABS(AF2)*100,"") -> 14.753419 | AI2: =IF(AH2="","N/A",IF(ABS(AH2)<3,"Neutral",IF(AH2>0,"Improvement","Deterioration"))) -> Improvement | AJ2: =IFERROR(AVERAGE(INDEX('Fundamentals Raw'!$A:$AG,BH2,7),INDEX('Fundamentals Raw'!$A:$AG,BH2,8),INDEX('Fundamentals Raw'!$A:$AG,BH2,9)),"") -> 16.683333 | AK2: =IFERROR(INDEX('Fundamentals Raw'!$A:$AG,BH2,9),"") -> 17.22 | AL2: =IFERROR((AK2-AJ2)/ABS(AJ2)*100,"") -> 3.2167832 | AM2: =IF(AL2="","N/A",IF(ABS(AL2)<3,"Neutral",IF(AL2>0,"Improvement","Deterioration"))) -> Improvement | AN2: =IFERROR(AVERAGE(((INDEX('Fundamentals Raw'!$A:$AG,BH2,11)-INDEX('Fundamentals Raw'!$A:$AG,BH2,10))/ABS(INDEX('Fundamentals Raw'!$A:$AG,BH2,10))),((INDEX('Fundamentals Raw'!$A:$AG,BH2,12)-INDEX('Fundamentals Raw'!$A:$AG,BH2,11))/ABS(INDEX('Fundamentals Raw'!$A:$AG,BH2,11))),((INDEX('Fundamentals Raw'!$A:$AG,BH2,13)-INDEX('Fundamentals Raw'!$A:$AG,BH2,12))/ABS(INDEX('Fundamentals Raw'!$A:$AG,BH2,12))))*100,"") -> 11.385632 | AO2: =IFERROR((((INDEX('Fundamentals Raw'!$A:$AG,BH2,13)-INDEX('Fundamentals Raw'!$A:$AG,BH2,12))/ABS(INDEX('Fundamentals Raw'!$A:$AG,BH2,12))))*100,"") -> 11.038598 | AP2: =IFERROR((AO2-AN2)/ABS(AN2)*100,"") -> -3.0480039 | AQ2: =IF(AP2="","N/A",IF(ABS(AP2)<3,"Neutral",IF(AP2>0,"Improvement","Deterioration"))) -> Deterioration | AR2: =IFERROR(AVERAGE(((INDEX('Fundamentals Raw'!$A:$AG,BH2,15)-INDEX('Fundamentals Raw'!$A:$AG,BH2,14))/ABS(INDEX('Fundamentals Raw'!$A:$AG,BH2,14))),((INDEX('Fundamentals Raw'!$A:$AG,BH2,16)-INDEX('Fundamentals Raw'!$A:$AG,BH2,15))/ABS(INDEX('Fundamentals Raw'!$A:$AG,BH2,15))),((INDEX('Fundamentals Raw'!$A:$AG,BH2,17)-INDEX('Fundamentals Raw'!$A:$AG,BH2,16))/ABS(INDEX('Fundamentals Raw'!$A:$AG,BH2,16))))*100,"") -> 8.8603724 | AS2: =IFERROR((((INDEX('Fundamentals Raw'!$A:$AG,BH2,17)-INDEX('Fundamentals Raw'!$A:$AG,BH2,16))/ABS(INDEX('Fundamentals Raw'!$A:$AG,BH2,16))))*100,"") -> 12.779861 | AT2: =IFERROR((AS2-AR2)/ABS(AR2)*100,"") -> 44.236158 | AU2: =IF(AT2="","N/A",IF(ABS(AT2)<3,"Neutral",IF(AT2>0,"Improvement","Deterioration"))) -> Improvement | AV2: =IFERROR(AVERAGE((INDEX('Fundamentals Raw'!$A:$AG,BH2,19)/INDEX('Fundamentals Raw'!$A:$AG,BH2,23)),(INDEX('Fundamentals Raw'!$A:$AG,BH2,20)/INDEX('Fundamentals Raw'!$A:$AG,BH2,24)),(INDEX('Fundamentals Raw'!$A:$AG,BH2,21)/INDEX('Fundamentals Raw'!$A:$AG,BH2,25))),"") -> 0.53003651 | AW2: =IFERROR((INDEX('Fundamentals Raw'!$A:$AG,BH2,21)/INDEX('Fundamentals Raw'!$A:$AG,BH2,25)),"") -> 0.58924736 | AX2: =IFERROR((AW2-AV2)/ABS(AV2)*100,"") -> 11.171089 | AY2: =IF(AX2="","N/A",IF(ABS(AX2)<3,"Neutral",IF(AX2>0,"Deterioration","Improvement"))) -> Deterioration | AZ2: =IFERROR(AVERAGE((INDEX('Fundamentals Raw'!$A:$AG,BH2,15)/INDEX('Fundamentals Raw'!$A:$AG,BH2,27)),(INDEX('Fundamentals Raw'!$A:$AG,BH2,16)/INDEX('Fundamentals Raw'!$A:$AG,BH2,28)),(INDEX('Fundamentals Raw'!$A:$AG,BH2,17)/INDEX('Fundamentals Raw'!$A:$AG,BH2,29))),"") -> 1.0871147 | BA2: =IFERROR((INDEX('Fundamentals Raw'!$A:$AG,BH2,17)/INDEX('Fundamentals Raw'!$A:$AG,BH2,29)),"") -> 1.1271206 | BB2: =IFERROR((BA2-AZ2)/ABS(AZ2)*100,"") -> 3.6800082 | BC2: =IF(BB2="","N/A",IF(ABS(BB2)<3,"Neutral",IF(BB2>0,"Improvement","Deterioration"))) -> Improvement | BD2: =IFERROR((INDEX('Fundamentals Raw'!$A:$AG,BH2,33))/(INDEX('Fundamentals Raw'!$A:$AG,BH2,29))*100,"") -> 6.4161478 | BE2: =IFERROR((D2/J2-1)*100,"") -> 0 | BF2: =IFERROR((D2/K2-1)*100,"") -> 22.607116 | BG2: =IFERROR(D2/K2,"") -> 1.2260712 | BH2: =IFERROR(MATCH(A2,'Fundamentals Raw'!$A:$A,0),"") -> 2 | BI2: =IFERROR(0.4*(D2/(SUMPRODUCT(('Price History'!$A$2:$A$1561=A2)*('Price History'!$E$2:$E$1561=64)*'Price History'!$C$2:$C$1561)))+0.2*(D2/(SUMPRODUCT(('Price History'!$A$2:$A$1561=A2)*('Price History'!$E$2:$E$1561=127)*'Price History'!$C$2:$C$1561)))+0.2*(D2/(SUMPRODUCT(('Price History'!$A$2:$A$1561=A2)*('Price History'!$E$2:$E$1561=190)*'Price History'!$C$2:$C$1561)))+0.2*(D2/(SUMPRODUCT(('Price History'!$A$2:$A$1561=A2)*('Price History'!$E$2:$E$1561=253)*'Price History'!$C$2:$C$1561))),"") -> 1.1193825 | BJ2: =IFERROR(IF(U2<60,"Red",IF(U2<80,"Amber","Green")),"") -> Amber | BK2: =IFERROR((S2-(AVERAGEIFS('Price History'!$C$2:$C$1561,'Price History'!$A$2:$A$1561,A2,'Price History'!$E$2:$E$1561,">=21",'Price History'!$E$2:$E$1561,"<=220")))/ABS(AVERAGEIFS('Price History'!$C$2:$C$1561,'Price History'!$A$2:$A$1561,A2,'Price History'!$E$2:$E$1561,">=21",'Price History'!$E$2:$E$1561,"<=220"))*100,"") -> 1.5875317 | BL2: =IFERROR(BK2>0,"") -> TRUE | BM2: =OR(C2="Banks",C2="Finance (including NBFCs)",C2="Housing Finance",C2="Microfinance Institutions",C2="Financial Institutions",C2="Asset Management Cos.",C2="Capital Markets",C2="Investment Companies",C2="General Insurance",C2="Life Insurance",C2="Other Financial Services") -> FALSE | BN2: =IFERROR(ROUND(100*(RANK(AF2,$AF$2:$AF$7,1)-1)/(COUNT($AF$2:$AF$7)-1),1),"") -> 60 | BO2: =IFERROR(ROUND(100*(RANK(AJ2,$AJ$2:$AJ$7,1)-1)/(COUNT($AJ$2:$AJ$7)-1),1),"") -> 80 | BP2: =IFERROR(ROUND(100*(RANK(AN2,$AN$2:$AN$7,1)-1)/(COUNT($AN$2:$AN$7)-1),1),"") -> 60 | BQ2: =IFERROR(ROUND(100*(RANK(AR2,$AR$2:$AR$7,1)-1)/(COUNT($AR$2:$AR$7)-1),1),"") -> 0 | BR2: =IFERROR(ROUND(100*(COUNT($AW$2:$AW$7)-RANK(AW2,$AW$2:$AW$7,1))/(COUNT($AW$2:$AW$7)-1),1),"") -> 0 | BS2: =IFERROR(ROUND(100*(RANK(BA2,$BA$2:$BA$7,1)-1)/(COUNT($BA$2:$BA$7)-1),1),"") -> 60 | BT2: =IFERROR(ROUND(100*(RANK(BD2,$BD$2:$BD$7,1)-1)/(COUNT($BD$2:$BD$7)-1),1),"") -> 40 | BU2: =IFERROR(MAX(0,MIN(100,MIN(IF(BM2,(BN2*0.2+BO2*0.325+BP2*0.325+BQ2*0.15),(BN2*0.2+BO2*0.15+BP2*0.15+BQ2*0.15+BR2*0.2+BS2*0.1+BT2*0.05))-(IF(AND(NOT(BM2),AW2<>"",AW2>2),20,0)),IF(AND(AN2<>"",AN2<0),40,999)))),"") -> 41 | BV2: =IFERROR(IF(BU2="","",IF((RANK(BU2,$BU$2:$BU$7,0)-1)/COUNT($BU$2:$BU$7)<0.2,"High",IF((RANK(BU2,$BU$2:$BU$7,0)-1)/COUNT($BU$2:$BU$7)<0.4,"Good",IF((RANK(BU2,$BU$2:$BU$7,0)-1)/COUNT($BU$2:$BU$7)<0.6,"Average",IF((RANK(BU2,$BU$2:$BU$7,0)-1)/COUNT($BU$2:$BU$7)<0.8,"Weak","Poor"))))),"") -> Weak
A3: ='Company Master'!A3 -> INE467B01029 | B3: ='Company Master'!C3 -> Tata Consultancy Services | C3: ='Company Master'!D3 -> IT | D3: =SUMPRODUCT(('Price History'!$A$2:$A$1561=A3)*('Price History'!$E$2:$E$1561=1)*'Price History'!$C$2:$C$1561) -> 3377.09 | E3: =D3-(SUMPRODUCT(('Price History'!$A$2:$A$1561=A3)*('Price History'!$E$2:$E$1561=2)*'Price History'!$C$2:$C$1561)) -> 25.69 | F3: =IFERROR(E3/(SUMPRODUCT(('Price History'!$A$2:$A$1561=A3)*('Price History'!$E$2:$E$1561=2)*'Price History'!$C$2:$C$1561)),"") -> 0.0076654532 | G3: ='Company Master'!E3 -> 1420000 | H3: =IFERROR(D3/(INDEX('Fundamentals Raw'!$A:$AG,BH3,13)),'Company Master'!F3) -> 57.297082 | I3: =IFERROR(L3/M3*100,"") -> 91.626396 | J3: =_xlfn.MAXIFS('Price History'!$C$2:$C$1561,'Price History'!$A$2:$A$1561,A3,'Price History'!$E$2:$E$1561,"<=252") -> 3440.01 | K3: =_xlfn.MINIFS('Price History'!$C$2:$C$1561,'Price History'!$A$2:$A$1561,A3,'Price History'!$E$2:$E$1561,"<=252") -> 2774.57 | L3: =SUMPRODUCT(('Price History'!$A$2:$A$1561=A3)*('Price History'!$E$2:$E$1561=1)*'Price History'!$D$2:$D$1561) -> 1399467 | M3: =AVERAGEIFS('Price History'!$D$2:$D$1561,'Price History'!$A$2:$A$1561,A3,'Price History'!$E$2:$E$1561,"<=30") -> 1527362.3 | N3: =IFERROR(AVERAGEIFS('Price History'!$C$2:$C$1561,'Price History'!$A$2:$A$1561,A3,'Price History'!$E$2:$E$1561,"<=3"),"") -> 3358.27 | O3: =IFERROR(AVERAGEIFS('Price History'!$C$2:$C$1561,'Price History'!$A$2:$A$1561,A3,'Price History'!$E$2:$E$1561,"<=8"),"") -> 3354.2463 | P3: =IFERROR(AVERAGEIFS('Price History'!$C$2:$C$1561,'Price History'!$A$2:$A$1561,A3,'Price History'!$E$2:$E$1561,"<=30"),"") -> 3371.4213 | Q3: =IFERROR(AVERAGEIFS('Price History'!$C$2:$C$1561,'Price History'!$A$2:$A$1561,A3,'Price History'!$E$2:$E$1561,"<=50"),"") -> 3360.7744 | R3: =IFERROR(AVERAGEIFS('Price History'!$C$2:$C$1561,'Price History'!$A$2:$A$1561,A3,'Price History'!$E$2:$E$1561,"<=100"),"") -> 3310.9021 | S3: =IFERROR(AVERAGEIFS('Price History'!$C$2:$C$1561,'Price History'!$A$2:$A$1561,A3,'Price History'!$E$2:$E$1561,"<=200"),"") -> 3208.7758 | T3: =IFERROR(100-100/(1+(AVERAGEIFS('Price History'!$G$2:$G$1561,'Price History'!$A$2:$A$1561,A3,'Price History'!$E$2:$E$1561,"<=14"))/(AVERAGEIFS('Price History'!$H$2:$H$1561,'Price History'!$A$2:$A$1561,A3,'Price History'!$E$2:$E$1561,"<=14"))),100) -> 40.267223 | U3: =IFERROR(ROUND(1+98*(RANK(BI3,$BI$2:$BI$7,1)-1)/(COUNT($BI$2:$BI$7)-1),0),"") -> 40 | V3: =IF(N3="","",D3>N3) -> TRUE | W3: =IF(O3="","",D3>O3) -> TRUE | X3: =IF(P3="","",D3>P3) -> TRUE | Y3: =IF(Q3="","",D3>Q3) -> TRUE | Z3: =IF(R3="","",D3>R3) -> TRUE | AA3: =IF(S3="","",D3>S3) -> TRUE | AB3: =IF(OR(N3="",O3=""),"",N3>O3) -> TRUE | AC3: =IF(OR(O3="",P3=""),"",O3>P3) -> FALSE | AD3: =IF(OR(P3="",R3=""),"",P3>R3) -> TRUE | AE3: =IF(OR(R3="",S3=""),"",R3>S3) -> TRUE | AF3: =IFERROR(AVERAGE(INDEX('Fundamentals Raw'!$A:$AG,BH3,3),INDEX('Fundamentals Raw'!$A:$AG,BH3,4),INDEX('Fundamentals Raw'!$A:$AG,BH3,5)),"") -> 16.25 | AG3: =IFERROR(INDEX('Fundamentals Raw'!$A:$AG,BH3,5),"") -> 13.83 | AH3: =IFERROR((AG3-AF3)/ABS(AF3)*100,"") -> -14.892308 | AI3: =IF(AH3="","N/A",IF(ABS(AH3)<3,"Neutral",IF(AH3>0,"Improvement","Deterioration"))) -> Deterioration | AJ3: =IFERROR(AVERAGE(INDEX('Fundamentals Raw'!$A:$AG,BH3,7),INDEX('Fundamentals Raw'!$A:$AG,BH3,8),INDEX('Fundamentals Raw'!$A:$AG,BH3,9)),"") -> 16.13 | AK3: =IFERROR(INDEX('Fundamentals Raw'!$A:$AG,BH3,9),"") -> 15.89 | AL3: =IFERROR((AK3-AJ3)/ABS(AJ3)*100,"") -> -1.4879107 | AM3: =IF(AL3="","N/A",IF(ABS(AL3)<3,"Neutral",IF(AL3>0,"Improvement","Deterioration"))) -> Neutral | AN3: =IFERROR(AVERAGE(((INDEX('Fundamentals Raw'!$A:$AG,BH3,11)-INDEX('Fundamentals Raw'!$A:$AG,BH3,10))/ABS(INDEX('Fundamentals Raw'!$A:$AG,BH3,10))),((INDEX('Fundamentals Raw'!$A:$AG,BH3,12)-INDEX('Fundamentals Raw'!$A:$AG,BH3,11))/ABS(INDEX('Fundamentals Raw'!$A:$AG,BH3,11))),((INDEX('Fundamentals Raw'!$A:$AG,BH3,13)-INDEX('Fundamentals Raw'!$A:$AG,BH3,12))/ABS(INDEX('Fundamentals Raw'!$A:$AG,BH3,12))))*100,"") -> 9.0814899 | AO3: =IFERROR((((INDEX('Fundamentals Raw'!$A:$AG,BH3,13)-INDEX('Fundamentals Raw'!$A:$AG,BH3,12))/ABS(INDEX('Fundamentals Raw'!$A:$AG,BH3,12))))*100,"") -> 12.760666 | AP3: =IFERROR((AO3-AN3)/ABS(AN3)*100,"") -> 40.51291 | AQ3: =IF(AP3="","N/A",IF(ABS(AP3)<3,"Neutral",IF(AP3>0,"Improvement","Deterioration"))) -> Improvement | AR3: =IFERROR(AVERAGE(((INDEX('Fundamentals Raw'!$A:$AG,BH3,15)-INDEX('Fundamentals Raw'!$A:$AG,BH3,14))/ABS(INDEX('Fundamentals Raw'!$A:$AG,BH3,14))),((INDEX('Fundamentals Raw'!$A:$AG,BH3,16)-INDEX('Fundamentals Raw'!$A:$AG,BH3,15))/ABS(INDEX('Fundamentals Raw'!$A:$AG,BH3,15))),((INDEX('Fundamentals Raw'!$A:$AG,BH3,17)-INDEX('Fundamentals Raw'!$A:$AG,BH3,16))/ABS(INDEX('Fundamentals Raw'!$A:$AG,BH3,16))))*100,"") -> 10.14133 | AS3: =IFERROR((((INDEX('Fundamentals Raw'!$A:$AG,BH3,17)-INDEX('Fundamentals Raw'!$A:$AG,BH3,16))/ABS(INDEX('Fundamentals Raw'!$A:$AG,BH3,16))))*100,"") -> 12.742986 | AT3: =IFERROR((AS3-AR3)/ABS(AR3)*100,"") -> 25.654 | AU3: =IF(AT3="","N/A",IF(ABS(AT3)<3,"Neutral",IF(AT3>0,"Improvement","Deterioration"))) -> Improvement | AV3: =IFERROR(AVERAGE((INDEX('Fundamentals Raw'!$A:$AG,BH3,19)/INDEX('Fundamentals Raw'!$A:$AG,BH3,23)),(INDEX('Fundamentals Raw'!$A:$AG,BH3,20)/INDEX('Fundamentals Raw'!$A:$AG,BH3,24)),(INDEX('Fundamentals Raw'!$A:$AG,BH3,21)/INDEX('Fundamentals Raw'!$A:$AG,BH3,25))),"") -> 0.39556779 | AW3: =IFERROR((INDEX('Fundamentals Raw'!$A:$AG,BH3,21)/INDEX('Fundamentals Raw'!$A:$AG,BH3,25)),"") -> 0.30709564 | AX3: =IFERROR((AW3-AV3)/ABS(AV3)*100,"") -> -22.365863 | AY3: =IF(AX3="","N/A",IF(ABS(AX3)<3,"Neutral",IF(AX3>0,"Deterioration","Improvement"))) -> Improvement | AZ3: =IFERROR(AVERAGE((INDEX('Fundamentals Raw'!$A:$AG,BH3,15)/INDEX('Fundamentals Raw'!$A:$AG,BH3,27)),(INDEX('Fundamentals Raw'!$A:$AG,BH3,16)/INDEX('Fundamentals Raw'!$A:$AG,BH3,28)),(INDEX('Fundamentals Raw'!$A:$AG,BH3,17)/INDEX('Fundamentals Raw'!$A:$AG,BH3,29))),"") -> 1.1235904 | BA3: =IFERROR((INDEX('Fundamentals Raw'!$A:$AG,BH3,17)/INDEX('Fundamentals Raw'!$A:$AG,BH3,29)),"") -> 1.0265884 | BB3: =IFERROR((BA3-AZ3)/ABS(AZ3)*100,"") -> -8.6332119 | BC3: =IF(BB3="","N/A",IF(ABS(BB3)<3,"Neutral",IF(BB3>0,"Improvement","Deterioration"))) -> Deterioration | BD3: =IFERROR((INDEX('Fundamentals Raw'!$A:$AG,BH3,33))/(INDEX('Fundamentals Raw'!$A:$AG,BH3,29))*100,"") -> 9.5431486 | BE3: =IFERROR((D3/J3-1)*100,"") -> -1.8290645 | BF3: =IFERROR((D3/K3-1)*100,"") -> 21.715797 | BG3: =IFERROR(D3/K3,"") -> 1.217158 | BH3: =IFERROR(MATCH(A3,'Fundamentals Raw'!$A:$A,0),"") -> 3 | BI3: =IFERROR(0.4*(D3/(SUMPRODUCT(('Price History'!$A$2:$A$1561=A3)*('Price History'!$E$2:$E$1561=64)*'Price History'!$C$2:$C$1561)))+0.2*(D3/(SUMPRODUCT(('Price History'!$A$2:$A$1561=A3)*('Price History'!$E$2:$E$1561=127)*'Price History'!$C$2:$C$1561)))+0.2*(D3/(SUMPRODUCT(('Price History'!$A$2:$A$1561=A3)*('Price History'!$E$2:$E$1561=190)*'Price History'!$C$2:$C$1561)))+0.2*(D3/(SUMPRODUCT(('Price History'!$A$2:$A$1561=A3)*('Price History'!$E$2:$E$1561=253)*'Price History'!$C$2:$C$1561))),"") -> 1.0824318 | BJ3: =IFERROR(IF(U3<60,"Red",IF(U3<80,"Amber","Green")),"") -> Red | BK3: =IFERROR((S3-(AVERAGEIFS('Price History'!$C$2:$C$1561,'Price History'!$A$2:$A$1561,A3,'Price History'!$E$2:$E$1561,">=21",'Price History'!$E$2:$E$1561,"<=220")))/ABS(AVERAGEIFS('Price History'!$C$2:$C$1561,'Price History'!$A$2:$A$1561,A3,'Price History'!$E$2:$E$1561,">=21",'Price History'!$E$2:$E$1561,"<=220"))*100,"") -> 1.1860454 | BL3: =IFERROR(BK3>0,"") -> TRUE | BM3: =OR(C3="Banks",C3="Finance (including NBFCs)",C3="Housing Finance",C3="Microfinance Institutions",C3="Financial Institutions",C3="Asset Management Cos.",C3="Capital Markets",C3="Investment Companies",C3="General Insurance",C3="Life Insurance",C3="Other Financial Services") -> FALSE | BN3: =IFERROR(ROUND(100*(RANK(AF3,$AF$2:$AF$7,1)-1)/(COUNT($AF$2:$AF$7)-1),1),"") -> 80 | BO3: =IFERROR(ROUND(100*(RANK(AJ3,$AJ$2:$AJ$7,1)-1)/(COUNT($AJ$2:$AJ$7)-1),1),"") -> 20 | BP3: =IFERROR(ROUND(100*(RANK(AN3,$AN$2:$AN$7,1)-1)/(COUNT($AN$2:$AN$7)-1),1),"") -> 0 | BQ3: =IFERROR(ROUND(100*(RANK(AR3,$AR$2:$AR$7,1)-1)/(COUNT($AR$2:$AR$7)-1),1),"") -> 60 | BR3: =IFERROR(ROUND(100*(COUNT($AW$2:$AW$7)-RANK(AW3,$AW$2:$AW$7,1))/(COUNT($AW$2:$AW$7)-1),1),"") -> 100 | BS3: =IFERROR(ROUND(100*(RANK(BA3,$BA$2:$BA$7,1)-1)/(COUNT($BA$2:$BA$7)-1),1),"") -> 20 | BT3: =IFERROR(ROUND(100*(RANK(BD3,$BD$2:$BD$7,1)-1)/(COUNT($BD$2:$BD$7)-1),1),"") -> 80 | BU3: =IFERROR(MAX(0,MIN(100,MIN(IF(BM3,(BN3*0.2+BO3*0.325+BP3*0.325+BQ3*0.15),(BN3*0.2+BO3*0.15+BP3*0.15+BQ3*0.15+BR3*0.2+BS3*0.1+BT3*0.05))-(IF(AND(NOT(BM3),AW3<>"",AW3>2),20,0)),IF(AND(AN3<>"",AN3<0),40,999)))),"") -> 54 | BV3: =IFERROR(IF(BU3="","",IF((RANK(BU3,$BU$2:$BU$7,0)-1)/COUNT($BU$2:$BU$7)<0.2,"High",IF((RANK(BU3,$BU$2:$BU$7,0)-1)/COUNT($BU$2:$BU$7)<0.4,"Good",IF((RANK(BU3,$BU$2:$BU$7,0)-1)/COUNT($BU$2:$BU$7)<0.6,"Average",IF((RANK(BU3,$BU$2:$BU$7,0)-1)/COUNT($BU$2:$BU$7)<0.8,"Weak","Poor"))))),"") -> Average
A4: ='Company Master'!A4 -> INE040A01034 | B4: ='Company Master'!C4 -> HDFC Bank | C4: ='Company Master'!D4 -> Banks | D4: =SUMPRODUCT(('Price History'!$A$2:$A$1561=A4)*('Price History'!$E$2:$E$1561=1)*'Price History'!$C$2:$C$1561) -> 2152.47 | E4: =D4-(SUMPRODUCT(('Price History'!$A$2:$A$1561=A4)*('Price History'!$E$2:$E$1561=2)*'Price History'!$C$2:$C$1561)) -> 17.82 | F4: =IFERROR(E4/(SUMPRODUCT(('Price History'!$A$2:$A$1561=A4)*('Price History'!$E$2:$E$1561=2)*'Price History'!$C$2:$C$1561)),"") -> 0.0083479727 | G4: ='Company Master'!E4 -> 1280000 | H4: =IFERROR(D4/(INDEX('Fundamentals Raw'!$A:$AG,BH4,13)),'Company Master'!F4) -> 33.4027 | I4: =IFERROR(L4/M4*100,"") -> 137.43583 | J4: =_xlfn.MAXIFS('Price History'!$C$2:$C$1561,'Price History'!$A$2:$A$1561,A4,'Price History'!$E$2:$E$1561,"<=252") -> 2189.55 | K4: =_xlfn.MINIFS('Price History'!$C$2:$C$1561,'Price History'!$A$2:$A$1561,A4,'Price History'!$E$2:$E$1561,"<=252") -> 1789 | L4: =SUMPRODUCT(('Price History'!$A$2:$A$1561=A4)*('Price History'!$E$2:$E$1561=1)*'Price History'!$D$2:$D$1561) -> 2090810 | M4: =AVERAGEIFS('Price History'!$D$2:$D$1561,'Price History'!$A$2:$A$1561,A4,'Price History'!$E$2:$E$1561,"<=30") -> 1521299.1 | N4: =IFERROR(AVERAGEIFS('Price History'!$C$2:$C$1561,'Price History'!$A$2:$A$1561,A4,'Price History'!$E$2:$E$1561,"<=3"),"") -> 2142.5533 | O4: =IFERROR(AVERAGEIFS('Price History'!$C$2:$C$1561,'Price History'!$A$2:$A$1561,A4,'Price History'!$E$2:$E$1561,"<=8"),"") -> 2156.09 | P4: =IFERROR(AVERAGEIFS('Price History'!$C$2:$C$1561,'Price History'!$A$2:$A$1561,A4,'Price History'!$E$2:$E$1561,"<=30"),"") -> 2153.9057 | Q4: =IFERROR(AVERAGEIFS('Price History'!$C$2:$C$1561,'Price History'!$A$2:$A$1561,A4,'Price History'!$E$2:$E$1561,"<=50"),"") -> 2127.8162 | R4: =IFERROR(AVERAGEIFS('Price History'!$C$2:$C$1561,'Price History'!$A$2:$A$1561,A4,'Price History'!$E$2:$E$1561,"<=100"),"") -> 2085.7139 | S4: =IFERROR(AVERAGEIFS('Price History'!$C$2:$C$1561,'Price History'!$A$2:$A$1561,A4,'Price History'!$E$2:$E$1561,"<=200"),"") -> 2037.2642 | T4: =IFERROR(100-100/(1+(AVERAGEIFS('Price History'!$G$2:$G$1561,'Price History'!$A$2:$A$1561,A4,'Price History'!$E$2:$E$1561,"<=14"))/(AVERAGEIFS('Price History'!$H$2:$H$1561,'Price History'!$A$2:$A$1561,A4,'Price History'!$E$2:$E$1561,"<=14"))),100) -> 36.515593 | U4: =IFERROR(ROUND(1+98*(RANK(BI4,$BI$2:$BI$7,1)-1)/(COUNT($BI$2:$BI$7)-1),0),"") -> 60 | V4: =IF(N4="","",D4>N4) -> TRUE | W4: =IF(O4="","",D4>O4) -> FALSE | X4: =IF(P4="","",D4>P4) -> FALSE | Y4: =IF(Q4="","",D4>Q4) -> TRUE | Z4: =IF(R4="","",D4>R4) -> TRUE | AA4: =IF(S4="","",D4>S4) -> TRUE | AB4: =IF(OR(N4="",O4=""),"",N4>O4) -> FALSE | AC4: =IF(OR(O4="",P4=""),"",O4>P4) -> TRUE | AD4: =IF(OR(P4="",R4=""),"",P4>R4) -> TRUE | AE4: =IF(OR(R4="",S4=""),"",R4>S4) -> TRUE | AF4: =IFERROR(AVERAGE(INDEX('Fundamentals Raw'!$A:$AG,BH4,3),INDEX('Fundamentals Raw'!$A:$AG,BH4,4),INDEX('Fundamentals Raw'!$A:$AG,BH4,5)),"") -> 16.01 | AG4: =IFERROR(INDEX('Fundamentals Raw'!$A:$AG,BH4,5),"") -> 17.45 | AH4: =IFERROR((AG4-AF4)/ABS(AF4)*100,"") -> 8.9943785 | AI4: =IF(AH4="","N/A",IF(ABS(AH4)<3,"Neutral",IF(AH4>0,"Improvement","Deterioration"))) -> Improvement | AJ4: =IFERROR(AVERAGE(INDEX('Fundamentals Raw'!$A:$AG,BH4,7),INDEX('Fundamentals Raw'!$A:$AG,BH4,8),INDEX('Fundamentals Raw'!$A:$AG,BH4,9)),"") -> 17.293333 | AK4: =IFERROR(INDEX('Fundamentals Raw'!$A:$AG,BH4,9),"") -> 15.6 | AL4: =IFERROR((AK4-AJ4)/ABS(AJ4)*100,"") -> -9.7918273 | AM4: =IF(AL4="","N/A",IF(ABS(AL4)<3,"Neutral",IF(AL4>0,"Improvement","Deterioration"))) -> Deterioration | AN4: =IFERROR(AVERAGE(((INDEX('Fundamentals Raw'!$A:$AG,BH4,11)-INDEX('Fundamentals Raw'!$A:$AG,BH4,10))/ABS(INDEX('Fundamentals Raw'!$A:$AG,BH4,10))),((INDEX('Fundamentals Raw'!$A:$AG,BH4,12)-INDEX('Fundamentals Raw'!$A:$AG,BH4,11))/ABS(INDEX('Fundamentals Raw'!$A:$AG,BH4,11))),((INDEX('Fundamentals Raw'!$A:$AG,BH4,13)-INDEX('Fundamentals Raw'!$A:$AG,BH4,12))/ABS(INDEX('Fundamentals Raw'!$A:$AG,BH4,12))))*100,"") -> 13.036246 | AO4: =IFERROR((((INDEX('Fundamentals Raw'!$A:$AG,BH4,13)-INDEX('Fundamentals Raw'!$A:$AG,BH4,12))/ABS(INDEX('Fundamentals Raw'!$A:$AG,BH4,12))))*100,"") -> 12.206164 | AP4: =IFERROR((AO4-AN4)/ABS(AN4)*100,"") -> -6.367492 | AQ4: =IF(AP4="","N/A",IF(ABS(AP4)<3,"Neutral",IF(AP4>0,"Improvement","Deterioration"))) -> Deterioration | AR4: =IFERROR(AVERAGE(((INDEX('Fundamentals Raw'!$A:$AG,BH4,15)-INDEX('Fundamentals Raw'!$A:$AG,BH4,14))/ABS(INDEX('Fundamentals Raw'!$A:$AG,BH4,14))),((INDEX('Fundamentals Raw'!$A:$AG,BH4,16)-INDEX('Fundamentals Raw'!$A:$AG,BH4,15))/ABS(INDEX('Fundamentals Raw'!$A:$AG,BH4,15))),((INDEX('Fundamentals Raw'!$A:$AG,BH4,17)-INDEX('Fundamentals Raw'!$A:$AG,BH4,16))/ABS(INDEX('Fundamentals Raw'!$A:$AG,BH4,16))))*100,"") -> 9.26264 | AS4: =IFERROR((((INDEX('Fundamentals Raw'!$A:$AG,BH4,17)-INDEX('Fundamentals Raw'!$A:$AG,BH4,16))/ABS(INDEX('Fundamentals Raw'!$A:$AG,BH4,16))))*100,"") -> 6.0916389 | AT4: =IFERROR((AS4-AR4)/ABS(AR4)*100,"") -> -34.234312 | AU4: =IF(AT4="","N/A",IF(ABS(AT4)<3,"Neutral",IF(AT4>0,"Improvement","Deterioration"))) -> Deterioration | AV4: =IFERROR(AVERAGE((INDEX('Fundamentals Raw'!$A:$AG,BH4,19)/INDEX('Fundamentals Raw'!$A:$AG,BH4,23)),(INDEX('Fundamentals Raw'!$A:$AG,BH4,20)/INDEX('Fundamentals Raw'!$A:$AG,BH4,24)),(INDEX('Fundamentals Raw'!$A:$AG,BH4,21)/INDEX('Fundamentals Raw'!$A:$AG,BH4,25))),"") -> 0.48621551 | AW4: =IFERROR((INDEX('Fundamentals Raw'!$A:$AG,BH4,21)/INDEX('Fundamentals Raw'!$A:$AG,BH4,25)),"") -> 0.45638601 | AX4: =IFERROR((AW4-AV4)/ABS(AV4)*100,"") -> -6.1350354 | AY4: =IF(AX4="","N/A",IF(ABS(AX4)<3,"Neutral",IF(AX4>0,"Deterioration","Improvement"))) -> Improvement | AZ4: =IFERROR(AVERAGE((INDEX('Fundamentals Raw'!$A:$AG,BH4,15)/INDEX('Fundamentals Raw'!$A:$AG,BH4,27)),(INDEX('Fundamentals Raw'!$A:$AG,BH4,16)/INDEX('Fundamentals Raw'!$A:$AG,BH4,28)),(INDEX('Fundamentals Raw'!$A:$AG,BH4,17)/INDEX('Fundamentals Raw'!$A:$AG,BH4,29))),"") -> 1.0463158 | BA4: =IFERROR((INDEX('Fundamentals Raw'!$A:$AG,BH4,17)/INDEX('Fundamentals Raw'!$A:$AG,BH4,29)),"") -> 0.96693074 | BB4: =IFERROR((BA4-AZ4)/ABS(AZ4)*100,"") -> -7.5871072 | BC4: =IF(BB4="","N/A",IF(ABS(BB4)<3,"Neutral",IF(BB4>0,"Improvement","Deterioration"))) -> Deterioration | BD4: =IFERROR((INDEX('Fundamentals Raw'!$A:$AG,BH4,33))/(INDEX('Fundamentals Raw'!$A:$AG,BH4,29))*100,"") -> 5.4781646 | BE4: =IFERROR((D4/J4-1)*100,"") -> -1.6934987 | BF4: =IFERROR((D4/K4-1)*100,"") -> 20.316937 | BG4: =IFERROR(D4/K4,"") -> 1.2031694 | BH4: =IFERROR(MATCH(A4,'Fundamentals Raw'!$A:$A,0),"") -> 4 | BI4: =IFERROR(0.4*(D4/(SUMPRODUCT(('Price History'!$A$2:$A$1561=A4)*('Price History'!$E$2:$E$1561=64)*'Price History'!$C$2:$C$1561)))+0.2*(D4/(SUMPRODUCT(('Price History'!$A$2:$A$1561=A4)*('Price History'!$E$2:$E$1561=127)*'Price History'!$C$2:$C$1561)))+0.2*(D4/(SUMPRODUCT(('Price History'!$A$2:$A$1561=A4)*('Price History'!$E$2:$E$1561=190)*'Price History'!$C$2:$C$1561)))+0.2*(D4/(SUMPRODUCT(('Price History'!$A$2:$A$1561=A4)*('Price History'!$E$2:$E$1561=253)*'Price History'!$C$2:$C$1561))),"") -> 1.1004332 | BJ4: =IFERROR(IF(U4<60,"Red",IF(U4<80,"Amber","Green")),"") -> Amber | BK4: =IFERROR((S4-(AVERAGEIFS('Price History'!$C$2:$C$1561,'Price History'!$A$2:$A$1561,A4,'Price History'!$E$2:$E$1561,">=21",'Price History'!$E$2:$E$1561,"<=220")))/ABS(AVERAGEIFS('Price History'!$C$2:$C$1561,'Price History'!$A$2:$A$1561,A4,'Price History'!$E$2:$E$1561,">=21",'Price History'!$E$2:$E$1561,"<=220"))*100,"") -> 1.1585421 | BL4: =IFERROR(BK4>0,"") -> TRUE | BM4: =OR(C4="Banks",C4="Finance (including NBFCs)",C4="Housing Finance",C4="Microfinance Institutions",C4="Financial Institutions",C4="Asset Management Cos.",C4="Capital Markets",C4="Investment Companies",C4="General Insurance",C4="Life Insurance",C4="Other Financial Services") -> TRUE | BN4: =IFERROR(ROUND(100*(RANK(AF4,$AF$2:$AF$7,1)-1)/(COUNT($AF$2:$AF$7)-1),1),"") -> 40 | BO4: =IFERROR(ROUND(100*(RANK(AJ4,$AJ$2:$AJ$7,1)-1)/(COUNT($AJ$2:$AJ$7)-1),1),"") -> 100 | BP4: =IFERROR(ROUND(100*(RANK(AN4,$AN$2:$AN$7,1)-1)/(COUNT($AN$2:$AN$7)-1),1),"") -> 100 | BQ4: =IFERROR(ROUND(100*(RANK(AR4,$AR$2:$AR$7,1)-1)/(COUNT($AR$2:$AR$7)-1),1),"") -> 20 | BR4: =IFERROR(ROUND(100*(COUNT($AW$2:$AW$7)-RANK(AW4,$AW$2:$AW$7,1))/(COUNT($AW$2:$AW$7)-1),1),"") -> 20 | BS4: =IFERROR(ROUND(100*(RANK(BA4,$BA$2:$BA$7,1)-1)/(COUNT($BA$2:$BA$7)-1),1),"") -> 0 | BT4: =IFERROR(ROUND(100*(RANK(BD4,$BD$2:$BD$7,1)-1)/(COUNT($BD$2:$BD$7)-1),1),"") -> 0 | BU4: =IFERROR(MAX(0,MIN(100,MIN(IF(BM4,(BN4*0.2+BO4*0.325+BP4*0.325+BQ4*0.15),(BN4*0.2+BO4*0.15+BP4*0.15+BQ4*0.15+BR4*0.2+BS4*0.1+BT4*0.05))-(IF(AND(NOT(BM4),AW4<>"",AW4>2),20,0)),IF(AND(AN4<>"",AN4<0),40,999)))),"") -> 76 | BV4: =IFERROR(IF(BU4="","",IF((RANK(BU4,$BU$2:$BU$7,0)-1)/COUNT($BU$2:$BU$7)<0.2,"High",IF((RANK(BU4,$BU$2:$BU$7,0)-1)/COUNT($BU$2:$BU$7)<0.4,"Good",IF((RANK(BU4,$BU$2:$BU$7,0)-1)/COUNT($BU$2:$BU$7)<0.6,"Average",IF((RANK(BU4,$BU$2:$BU$7,0)-1)/COUNT($BU$2:$BU$7)<0.8,"Weak","Poor"))))),"") -> High
A5: ='Company Master'!A5 -> INE154A01025 | B5: ='Company Master'!C5 -> ITC Ltd | C5: ='Company Master'!D5 -> FMCG | D5: =SUMPRODUCT(('Price History'!$A$2:$A$1561=A5)*('Price History'!$E$2:$E$1561=1)*'Price History'!$C$2:$C$1561) -> 2299.15 | E5: =D5-(SUMPRODUCT(('Price History'!$A$2:$A$1561=A5)*('Price History'!$E$2:$E$1561=2)*'Price History'!$C$2:$C$1561)) -> -7.42 | F5: =IFERROR(E5/(SUMPRODUCT(('Price History'!$A$2:$A$1561=A5)*('Price History'!$E$2:$E$1561=2)*'Price History'!$C$2:$C$1561)),"") -> -0.0032168978 | G5: ='Company Master'!E5 -> 540000 | H5: =IFERROR(D5/(INDEX('Fundamentals Raw'!$A:$AG,BH5,13)),'Company Master'!F5) -> 37.017389 | I5: =IFERROR(L5/M5*100,"") -> 123.76593 | J5: =_xlfn.MAXIFS('Price History'!$C$2:$C$1561,'Price History'!$A$2:$A$1561,A5,'Price History'!$E$2:$E$1561,"<=252") -> 2489.74 | K5: =_xlfn.MINIFS('Price History'!$C$2:$C$1561,'Price History'!$A$2:$A$1561,A5,'Price History'!$E$2:$E$1561,"<=252") -> 2222.61 | L5: =SUMPRODUCT(('Price History'!$A$2:$A$1561=A5)*('Price History'!$E$2:$E$1561=1)*'Price History'!$D$2:$D$1561) -> 1885670 | M5: =AVERAGEIFS('Price History'!$D$2:$D$1561,'Price History'!$A$2:$A$1561,A5,'Price History'!$E$2:$E$1561,"<=30") -> 1523577.6 | N5: =IFERROR(AVERAGEIFS('Price History'!$C$2:$C$1561,'Price History'!$A$2:$A$1561,A5,'Price History'!$E$2:$E$1561,"<=3"),"") -> 2300.81 | O5: =IFERROR(AVERAGEIFS('Price History'!$C$2:$C$1561,'Price History'!$A$2:$A$1561,A5,'Price History'!$E$2:$E$1561,"<=8"),"") -> 2281.5738 | P5: =IFERROR(AVERAGEIFS('Price History'!$C$2:$C$1561,'Price History'!$A$2:$A$1561,A5,'Price History'!$E$2:$E$1561,"<=30"),"") -> 2266.4673 | Q5: =IFERROR(AVERAGEIFS('Price History'!$C$2:$C$1561,'Price History'!$A$2:$A$1561,A5,'Price History'!$E$2:$E$1561,"<=50"),"") -> 2294.4624 | R5: =IFERROR(AVERAGEIFS('Price History'!$C$2:$C$1561,'Price History'!$A$2:$A$1561,A5,'Price History'!$E$2:$E$1561,"<=100"),"") -> 2326.0617 | S5: =IFERROR(AVERAGEIFS('Price History'!$C$2:$C$1561,'Price History'!$A$2:$A$1561,A5,'Price History'!$E$2:$E$1561,"<=200"),"") -> 2378.4453 | T5: =IFERROR(100-100/(1+(AVERAGEIFS('Price History'!$G$2:$G$1561,'Price History'!$A$2:$A$1561,A5,'Price History'!$E$2:$E$1561,"<=14"))/(AVERAGEIFS('Price History'!$H$2:$H$1561,'Price History'!$A$2:$A$1561,A5,'Price History'!$E$2:$E$1561,"<=14"))),100) -> 63.924992 | U5: =IFERROR(ROUND(1+98*(RANK(BI5,$BI$2:$BI$7,1)-1)/(COUNT($BI$2:$BI$7)-1),0),"") -> 1 | V5: =IF(N5="","",D5>N5) -> FALSE | W5: =IF(O5="","",D5>O5) -> TRUE | X5: =IF(P5="","",D5>P5) -> TRUE | Y5: =IF(Q5="","",D5>Q5) -> TRUE | Z5: =IF(R5="","",D5>R5) -> FALSE | AA5: =IF(S5="","",D5>S5) -> FALSE | AB5: =IF(OR(N5="",O5=""),"",N5>O5) -> TRUE | AC5: =IF(OR(O5="",P5=""),"",O5>P5) -> TRUE | AD5: =IF(OR(P5="",R5=""),"",P5>R5) -> FALSE | AE5: =IF(OR(R5="",S5=""),"",R5>S5) -> FALSE | AF5: =IFERROR(AVERAGE(INDEX('Fundamentals Raw'!$A:$AG,BH5,3),INDEX('Fundamentals Raw'!$A:$AG,BH5,4),INDEX('Fundamentals Raw'!$A:$AG,BH5,5)),"") -> 18.293333 | AG5: =IFERROR(INDEX('Fundamentals Raw'!$A:$AG,BH5,5),"") -> 18.13 | AH5: =IFERROR((AG5-AF5)/ABS(AF5)*100,"") -> -0.89285714 | AI5: =IF(AH5="","N/A",IF(ABS(AH5)<3,"Neutral",IF(AH5>0,"Improvement","Deterioration"))) -> Neutral | AJ5: =IFERROR(AVERAGE(INDEX('Fundamentals Raw'!$A:$AG,BH5,7),INDEX('Fundamentals Raw'!$A:$AG,BH5,8),INDEX('Fundamentals Raw'!$A:$AG,BH5,9)),"") -> 16.623333 | AK5: =IFERROR(INDEX('Fundamentals Raw'!$A:$AG,BH5,9),"") -> 16.85 | AL5: =IFERROR((AK5-AJ5)/ABS(AJ5)*100,"") -> 1.3635452 | AM5: =IF(AL5="","N/A",IF(ABS(AL5)<3,"Neutral",IF(AL5>0,"Improvement","Deterioration"))) -> Neutral | AN5: =IFERROR(AVERAGE(((INDEX('Fundamentals Raw'!$A:$AG,BH5,11)-INDEX('Fundamentals Raw'!$A:$AG,BH5,10))/ABS(INDEX('Fundamentals Raw'!$A:$AG,BH5,10))),((INDEX('Fundamentals Raw'!$A:$AG,BH5,12)-INDEX('Fundamentals Raw'!$A:$AG,BH5,11))/ABS(INDEX('Fundamentals Raw'!$A:$AG,BH5,11))),((INDEX('Fundamentals Raw'!$A:$AG,BH5,13)-INDEX('Fundamentals Raw'!$A:$AG,BH5,12))/ABS(INDEX('Fundamentals Raw'!$A:$AG,BH5,12))))*100,"") -> 10.976511 | AO5: =IFERROR((((INDEX('Fundamentals Raw'!$A:$AG,BH5,13)-INDEX('Fundamentals Raw'!$A:$AG,BH5,12))/ABS(INDEX('Fundamentals Raw'!$A:$AG,BH5,12))))*100,"") -> 12.59971 | AP5: =IFERROR((AO5-AN5)/ABS(AN5)*100,"") -> 14.787927 | AQ5: =IF(AP5="","N/A",IF(ABS(AP5)<3,"Neutral",IF(AP5>0,"Improvement","Deterioration"))) -> Improvement | AR5: =IFERROR(AVERAGE(((INDEX('Fundamentals Raw'!$A:$AG,BH5,15)-INDEX('Fundamentals Raw'!$A:$AG,BH5,14))/ABS(INDEX('Fundamentals Raw'!$A:$AG,BH5,14))),((INDEX('Fundamentals Raw'!$A:$AG,BH5,16)-INDEX('Fundamentals Raw'!$A:$AG,BH5,15))/ABS(INDEX('Fundamentals Raw'!$A:$AG,BH5,15))),((INDEX('Fundamentals Raw'!$A:$AG,BH5,17)-INDEX('Fundamentals Raw'!$A:$AG,BH5,16))/ABS(INDEX('Fundamentals Raw'!$A:$AG,BH5,16))))*100,"") -> 10.286079 | AS5: =IFERROR((((INDEX('Fundamentals Raw'!$A:$AG,BH5,17)-INDEX('Fundamentals Raw'!$A:$AG,BH5,16))/ABS(INDEX('Fundamentals Raw'!$A:$AG,BH5,16))))*100,"") -> 6.5535399 | AT5: =IFERROR((AS5-AR5)/ABS(AR5)*100,"") -> -36.287286 | AU5: =IF(AT5="","N/A",IF(ABS(AT5)<3,"Neutral",IF(AT5>0,"Improvement","Deterioration"))) -> Deterioration | AV5: =IFERROR(AVERAGE((INDEX('Fundamentals Raw'!$A:$AG,BH5,19)/INDEX('Fundamentals Raw'!$A:$AG,BH5,23)),(INDEX('Fundamentals Raw'!$A:$AG,BH5,20)/INDEX('Fundamentals Raw'!$A:$AG,BH5,24)),(INDEX('Fundamentals Raw'!$A:$AG,BH5,21)/INDEX('Fundamentals Raw'!$A:$AG,BH5,25))),"") -> 0.46108936 | AW5: =IFERROR((INDEX('Fundamentals Raw'!$A:$AG,BH5,21)/INDEX('Fundamentals Raw'!$A:$AG,BH5,25)),"") -> 0.4199228 | AX5: =IFERROR((AW5-AV5)/ABS(AV5)*100,"") -> -8.9281103 | AY5: =IF(AX5="","N/A",IF(ABS(AX5)<3,"Neutral",IF(AX5>0,"Deterioration","Improvement"))) -> Improvement | AZ5: =IFERROR(AVERAGE((INDEX('Fundamentals Raw'!$A:$AG,BH5,15)/INDEX('Fundamentals Raw'!$A:$AG,BH5,27)),(INDEX('Fundamentals Raw'!$A:$AG,BH5,16)/INDEX('Fundamentals Raw'!$A:$AG,BH5,28)),(INDEX('Fundamentals Raw'!$A:$AG,BH5,17)/INDEX('Fundamentals Raw'!$A:$AG,BH5,29))),"") -> 1.1425158 | BA5: =IFERROR((INDEX('Fundamentals Raw'!$A:$AG,BH5,17)/INDEX('Fundamentals Raw'!$A:$AG,BH5,29)),"") -> 1.0590326 | BB5: =IFERROR((BA5-AZ5)/ABS(AZ5)*100,"") -> -7.306962 | BC5: =IF(BB5="","N/A",IF(ABS(BB5)<3,"Neutral",IF(BB5>0,"Improvement","Deterioration"))) -> Deterioration | BD5: =IFERROR((INDEX('Fundamentals Raw'!$A:$AG,BH5,33))/(INDEX('Fundamentals Raw'!$A:$AG,BH5,29))*100,"") -> 8.9793789 | BE5: =IFERROR((D5/J5-1)*100,"") -> -7.6550162 | BF5: =IFERROR((D5/K5-1)*100,"") -> 3.4436991 | BG5: =IFERROR(D5/K5,"") -> 1.034437 | BH5: =IFERROR(MATCH(A5,'Fundamentals Raw'!$A:$A,0),"") -> 5 | BI5: =IFERROR(0.4*(D5/(SUMPRODUCT(('Price History'!$A$2:$A$1561=A5)*('Price History'!$E$2:$E$1561=64)*'Price History'!$C$2:$C$1561)))+0.2*(D5/(SUMPRODUCT(('Price History'!$A$2:$A$1561=A5)*('Price History'!$E$2:$E$1561=127)*'Price History'!$C$2:$C$1561)))+0.2*(D5/(SUMPRODUCT(('Price History'!$A$2:$A$1561=A5)*('Price History'!$E$2:$E$1561=190)*'Price History'!$C$2:$C$1561)))+0.2*(D5/(SUMPRODUCT(('Price History'!$A$2:$A$1561=A5)*('Price History'!$E$2:$E$1561=253)*'Price History'!$C$2:$C$1561))),"") -> 0.97185263 | BJ5: =IFERROR(IF(U5<60,"Red",IF(U5<80,"Amber","Green")),"") -> Red | BK5: =IFERROR((S5-(AVERAGEIFS('Price History'!$C$2:$C$1561,'Price History'!$A$2:$A$1561,A5,'Price History'!$E$2:$E$1561,">=21",'Price History'!$E$2:$E$1561,"<=220")))/ABS(AVERAGEIFS('Price History'!$C$2:$C$1561,'Price History'!$A$2:$A$1561,A5,'Price History'!$E$2:$E$1561,">=21",'Price History'!$E$2:$E$1561,"<=220"))*100,"") -> -0.75787302 | BL5: =IFERROR(BK5>0,"") -> FALSE | BM5: =OR(C5="Banks",C5="Finance (including NBFCs)",C5="Housing Finance",C5="Microfinance Institutions",C5="Financial Institutions",C5="Asset Management Cos.",C5="Capital Markets",C5="Investment Companies",C5="General Insurance",C5="Life Insurance",C5="Other Financial Services") -> FALSE | BN5: =IFERROR(ROUND(100*(RANK(AF5,$AF$2:$AF$7,1)-1)/(COUNT($AF$2:$AF$7)-1),1),"") -> 100 | BO5: =IFERROR(ROUND(100*(RANK(AJ5,$AJ$2:$AJ$7,1)-1)/(COUNT($AJ$2:$AJ$7)-1),1),"") -> 60 | BP5: =IFERROR(ROUND(100*(RANK(AN5,$AN$2:$AN$7,1)-1)/(COUNT($AN$2:$AN$7)-1),1),"") -> 20 | BQ5: =IFERROR(ROUND(100*(RANK(AR5,$AR$2:$AR$7,1)-1)/(COUNT($AR$2:$AR$7)-1),1),"") -> 80 | BR5: =IFERROR(ROUND(100*(COUNT($AW$2:$AW$7)-RANK(AW5,$AW$2:$AW$7,1))/(COUNT($AW$2:$AW$7)-1),1),"") -> 40 | BS5: =IFERROR(ROUND(100*(RANK(BA5,$BA$2:$BA$7,1)-1)/(COUNT($BA$2:$BA$7)-1),1),"") -> 40 | BT5: =IFERROR(ROUND(100*(RANK(BD5,$BD$2:$BD$7,1)-1)/(COUNT($BD$2:$BD$7)-1),1),"") -> 60 | BU5: =IFERROR(MAX(0,MIN(100,MIN(IF(BM5,(BN5*0.2+BO5*0.325+BP5*0.325+BQ5*0.15),(BN5*0.2+BO5*0.15+BP5*0.15+BQ5*0.15+BR5*0.2+BS5*0.1+BT5*0.05))-(IF(AND(NOT(BM5),AW5<>"",AW5>2),20,0)),IF(AND(AN5<>"",AN5<0),40,999)))),"") -> 59 | BV5: =IFERROR(IF(BU5="","",IF((RANK(BU5,$BU$2:$BU$7,0)-1)/COUNT($BU$2:$BU$7)<0.2,"High",IF((RANK(BU5,$BU$2:$BU$7,0)-1)/COUNT($BU$2:$BU$7)<0.4,"Good",IF((RANK(BU5,$BU$2:$BU$7,0)-1)/COUNT($BU$2:$BU$7)<0.6,"Average",IF((RANK(BU5,$BU$2:$BU$7,0)-1)/COUNT($BU$2:$BU$7)<0.8,"Weak","Poor"))))),"") -> Good
A6: ='Company Master'!A6 -> INE075A01022 | B6: ='Company Master'!C6 -> Wipro Ltd | C6: ='Company Master'!D6 -> IT | D6: =SUMPRODUCT(('Price History'!$A$2:$A$1561=A6)*('Price History'!$E$2:$E$1561=1)*'Price History'!$C$2:$C$1561) -> 2569.5 | E6: =D6-(SUMPRODUCT(('Price History'!$A$2:$A$1561=A6)*('Price History'!$E$2:$E$1561=2)*'Price History'!$C$2:$C$1561)) -> 9.54 | F6: =IFERROR(E6/(SUMPRODUCT(('Price History'!$A$2:$A$1561=A6)*('Price History'!$E$2:$E$1561=2)*'Price History'!$C$2:$C$1561)),"") -> 0.0037266207 | G6: ='Company Master'!E6 -> 260000 | H6: =IFERROR(D6/(INDEX('Fundamentals Raw'!$A:$AG,BH6,13)),'Company Master'!F6) -> 42.324164 | I6: =IFERROR(L6/M6*100,"") -> 83.027658 | J6: =_xlfn.MAXIFS('Price History'!$C$2:$C$1561,'Price History'!$A$2:$A$1561,A6,'Price History'!$E$2:$E$1561,"<=252") -> 2582.84 | K6: =_xlfn.MINIFS('Price History'!$C$2:$C$1561,'Price History'!$A$2:$A$1561,A6,'Price History'!$E$2:$E$1561,"<=252") -> 2082.67 | L6: =SUMPRODUCT(('Price History'!$A$2:$A$1561=A6)*('Price History'!$E$2:$E$1561=1)*'Price History'!$D$2:$D$1561) -> 1020333 | M6: =AVERAGEIFS('Price History'!$D$2:$D$1561,'Price History'!$A$2:$A$1561,A6,'Price History'!$E$2:$E$1561,"<=30") -> 1228907.4 | N6: =IFERROR(AVERAGEIFS('Price History'!$C$2:$C$1561,'Price History'!$A$2:$A$1561,A6,'Price History'!$E$2:$E$1561,"<=3"),"") -> 2564.8967 | O6: =IFERROR(AVERAGEIFS('Price History'!$C$2:$C$1561,'Price History'!$A$2:$A$1561,A6,'Price History'!$E$2:$E$1561,"<=8"),"") -> 2563.2925 | P6: =IFERROR(AVERAGEIFS('Price History'!$C$2:$C$1561,'Price History'!$A$2:$A$1561,A6,'Price History'!$E$2:$E$1561,"<=30"),"") -> 2538.214 | Q6: =IFERROR(AVERAGEIFS('Price History'!$C$2:$C$1561,'Price History'!$A$2:$A$1561,A6,'Price History'!$E$2:$E$1561,"<=50"),"") -> 2496.0658 | R6: =IFERROR(AVERAGEIFS('Price History'!$C$2:$C$1561,'Price History'!$A$2:$A$1561,A6,'Price History'!$E$2:$E$1561,"<=100"),"") -> 2430.5946 | S6: =IFERROR(AVERAGEIFS('Price History'!$C$2:$C$1561,'Price History'!$A$2:$A$1561,A6,'Price History'!$E$2:$E$1561,"<=200"),"") -> 2328.3431 | T6: =IFERROR(100-100/(1+(AVERAGEIFS('Price History'!$G$2:$G$1561,'Price History'!$A$2:$A$1561,A6,'Price History'!$E$2:$E$1561,"<=14"))/(AVERAGEIFS('Price History'!$H$2:$H$1561,'Price History'!$A$2:$A$1561,A6,'Price History'!$E$2:$E$1561,"<=14"))),100) -> 46.76178 | U6: =IFERROR(ROUND(1+98*(RANK(BI6,$BI$2:$BI$7,1)-1)/(COUNT($BI$2:$BI$7)-1),0),"") -> 99 | V6: =IF(N6="","",D6>N6) -> TRUE | W6: =IF(O6="","",D6>O6) -> TRUE | X6: =IF(P6="","",D6>P6) -> TRUE | Y6: =IF(Q6="","",D6>Q6) -> TRUE | Z6: =IF(R6="","",D6>R6) -> TRUE | AA6: =IF(S6="","",D6>S6) -> TRUE | AB6: =IF(OR(N6="",O6=""),"",N6>O6) -> TRUE | AC6: =IF(OR(O6="",P6=""),"",O6>P6) -> TRUE | AD6: =IF(OR(P6="",R6=""),"",P6>R6) -> TRUE | AE6: =IF(OR(R6="",S6=""),"",R6>S6) -> TRUE | AF6: =IFERROR(AVERAGE(INDEX('Fundamentals Raw'!$A:$AG,BH6,3),INDEX('Fundamentals Raw'!$A:$AG,BH6,4),INDEX('Fundamentals Raw'!$A:$AG,BH6,5)),"") -> 15.243333 | AG6: =IFERROR(INDEX('Fundamentals Raw'!$A:$AG,BH6,5),"") -> 18.46 | AH6: =IFERROR((AG6-AF6)/ABS(AF6)*100,"") -> 21.102121 | AI6: =IF(AH6="","N/A",IF(ABS(AH6)<3,"Neutral",IF(AH6>0,"Improvement","Deterioration"))) -> Improvement | AJ6: =IFERROR(AVERAGE(INDEX('Fundamentals Raw'!$A:$AG,BH6,7),INDEX('Fundamentals Raw'!$A:$AG,BH6,8),INDEX('Fundamentals Raw'!$A:$AG,BH6,9)),"") -> 15.99 | AK6: =IFERROR(INDEX('Fundamentals Raw'!$A:$AG,BH6,9),"") -> 14.58 | AL6: =IFERROR((AK6-AJ6)/ABS(AJ6)*100,"") -> -8.8180113 | AM6: =IF(AL6="","N/A",IF(ABS(AL6)<3,"Neutral",IF(AL6>0,"Improvement","Deterioration"))) -> Deterioration | AN6: =IFERROR(AVERAGE(((INDEX('Fundamentals Raw'!$A:$AG,BH6,11)-INDEX('Fundamentals Raw'!$A:$AG,BH6,10))/ABS(INDEX('Fundamentals Raw'!$A:$AG,BH6,10))),((INDEX('Fundamentals Raw'!$A:$AG,BH6,12)-INDEX('Fundamentals Raw'!$A:$AG,BH6,11))/ABS(INDEX('Fundamentals Raw'!$A:$AG,BH6,11))),((INDEX('Fundamentals Raw'!$A:$AG,BH6,13)-INDEX('Fundamentals Raw'!$A:$AG,BH6,12))/ABS(INDEX('Fundamentals Raw'!$A:$AG,BH6,12))))*100,"") -> 11.229405 | AO6: =IFERROR((((INDEX('Fundamentals Raw'!$A:$AG,BH6,13)-INDEX('Fundamentals Raw'!$A:$AG,BH6,12))/ABS(INDEX('Fundamentals Raw'!$A:$AG,BH6,12))))*100,"") -> 12.843866 | AP6: =IFERROR((AO6-AN6)/ABS(AN6)*100,"") -> 14.377082 | AQ6: =IF(AP6="","N/A",IF(ABS(AP6)<3,"Neutral",IF(AP6>0,"Improvement","Deterioration"))) -> Improvement | AR6: =IFERROR(AVERAGE(((INDEX('Fundamentals Raw'!$A:$AG,BH6,15)-INDEX('Fundamentals Raw'!$A:$AG,BH6,14))/ABS(INDEX('Fundamentals Raw'!$A:$AG,BH6,14))),((INDEX('Fundamentals Raw'!$A:$AG,BH6,16)-INDEX('Fundamentals Raw'!$A:$AG,BH6,15))/ABS(INDEX('Fundamentals Raw'!$A:$AG,BH6,15))),((INDEX('Fundamentals Raw'!$A:$AG,BH6,17)-INDEX('Fundamentals Raw'!$A:$AG,BH6,16))/ABS(INDEX('Fundamentals Raw'!$A:$AG,BH6,16))))*100,"") -> 9.9975525 | AS6: =IFERROR((((INDEX('Fundamentals Raw'!$A:$AG,BH6,17)-INDEX('Fundamentals Raw'!$A:$AG,BH6,16))/ABS(INDEX('Fundamentals Raw'!$A:$AG,BH6,16))))*100,"") -> 9.7815714 | AT6: =IFERROR((AS6-AR6)/ABS(AR6)*100,"") -> -2.1603402 | AU6: =IF(AT6="","N/A",IF(ABS(AT6)<3,"Neutral",IF(AT6>0,"Improvement","Deterioration"))) -> Neutral | AV6: =IFERROR(AVERAGE((INDEX('Fundamentals Raw'!$A:$AG,BH6,19)/INDEX('Fundamentals Raw'!$A:$AG,BH6,23)),(INDEX('Fundamentals Raw'!$A:$AG,BH6,20)/INDEX('Fundamentals Raw'!$A:$AG,BH6,24)),(INDEX('Fundamentals Raw'!$A:$AG,BH6,21)/INDEX('Fundamentals Raw'!$A:$AG,BH6,25))),"") -> 0.31540207 | AW6: =IFERROR((INDEX('Fundamentals Raw'!$A:$AG,BH6,21)/INDEX('Fundamentals Raw'!$A:$AG,BH6,25)),"") -> 0.37242259 | AX6: =IFERROR((AW6-AV6)/ABS(AV6)*100,"") -> 18.078676 | AY6: =IF(AX6="","N/A",IF(ABS(AX6)<3,"Neutral",IF(AX6>0,"Deterioration","Improvement"))) -> Deterioration | AZ6: =IFERROR(AVERAGE((INDEX('Fundamentals Raw'!$A:$AG,BH6,15)/INDEX('Fundamentals Raw'!$A:$AG,BH6,27)),(INDEX('Fundamentals Raw'!$A:$AG,BH6,16)/INDEX('Fundamentals Raw'!$A:$AG,BH6,28)),(INDEX('Fundamentals Raw'!$A:$AG,BH6,17)/INDEX('Fundamentals Raw'!$A:$AG,BH6,29))),"") -> 1.0253754 | BA6: =IFERROR((INDEX('Fundamentals Raw'!$A:$AG,BH6,17)/INDEX('Fundamentals Raw'!$A:$AG,BH6,29)),"") -> 1.1541453 | BB6: =IFERROR((BA6-AZ6)/ABS(AZ6)*100,"") -> 12.55831 | BC6: =IF(BB6="","N/A",IF(ABS(BB6)<3,"Neutral",IF(BB6>0,"Improvement","Deterioration"))) -> Improvement | BD6: =IFERROR((INDEX('Fundamentals Raw'!$A:$AG,BH6,33))/(INDEX('Fundamentals Raw'!$A:$AG,BH6,29))*100,"") -> 5.7362748 | BE6: =IFERROR((D6/J6-1)*100,"") -> -0.51648573 | BF6: =IFERROR((D6/K6-1)*100,"") -> 23.375283 | BG6: =IFERROR(D6/K6,"") -> 1.2337528 | BH6: =IFERROR(MATCH(A6,'Fundamentals Raw'!$A:$A,0),"") -> 6 | BI6: =IFERROR(0.4*(D6/(SUMPRODUCT(('Price History'!$A$2:$A$1561=A6)*('Price History'!$E$2:$E$1561=64)*'Price History'!$C$2:$C$1561)))+0.2*(D6/(SUMPRODUCT(('Price History'!$A$2:$A$1561=A6)*('Price History'!$E$2:$E$1561=127)*'Price History'!$C$2:$C$1561)))+0.2*(D6/(SUMPRODUCT(('Price History'!$A$2:$A$1561=A6)*('Price History'!$E$2:$E$1561=190)*'Price History'!$C$2:$C$1561)))+0.2*(D6/(SUMPRODUCT(('Price History'!$A$2:$A$1561=A6)*('Price History'!$E$2:$E$1561=253)*'Price History'!$C$2:$C$1561))),"") -> 1.1427259 | BJ6: =IFERROR(IF(U6<60,"Red",IF(U6<80,"Amber","Green")),"") -> Green | BK6: =IFERROR((S6-(AVERAGEIFS('Price History'!$C$2:$C$1561,'Price History'!$A$2:$A$1561,A6,'Price History'!$E$2:$E$1561,">=21",'Price History'!$E$2:$E$1561,"<=220")))/ABS(AVERAGEIFS('Price History'!$C$2:$C$1561,'Price History'!$A$2:$A$1561,A6,'Price History'!$E$2:$E$1561,">=21",'Price History'!$E$2:$E$1561,"<=220"))*100,"") -> 1.8866402 | BL6: =IFERROR(BK6>0,"") -> TRUE | BM6: =OR(C6="Banks",C6="Finance (including NBFCs)",C6="Housing Finance",C6="Microfinance Institutions",C6="Financial Institutions",C6="Asset Management Cos.",C6="Capital Markets",C6="Investment Companies",C6="General Insurance",C6="Life Insurance",C6="Other Financial Services") -> FALSE | BN6: =IFERROR(ROUND(100*(RANK(AF6,$AF$2:$AF$7,1)-1)/(COUNT($AF$2:$AF$7)-1),1),"") -> 0 | BO6: =IFERROR(ROUND(100*(RANK(AJ6,$AJ$2:$AJ$7,1)-1)/(COUNT($AJ$2:$AJ$7)-1),1),"") -> 0 | BP6: =IFERROR(ROUND(100*(RANK(AN6,$AN$2:$AN$7,1)-1)/(COUNT($AN$2:$AN$7)-1),1),"") -> 40 | BQ6: =IFERROR(ROUND(100*(RANK(AR6,$AR$2:$AR$7,1)-1)/(COUNT($AR$2:$AR$7)-1),1),"") -> 40 | BR6: =IFERROR(ROUND(100*(COUNT($AW$2:$AW$7)-RANK(AW6,$AW$2:$AW$7,1))/(COUNT($AW$2:$AW$7)-1),1),"") -> 60 | BS6: =IFERROR(ROUND(100*(RANK(BA6,$BA$2:$BA$7,1)-1)/(COUNT($BA$2:$BA$7)-1),1),"") -> 80 | BT6: =IFERROR(ROUND(100*(RANK(BD6,$BD$2:$BD$7,1)-1)/(COUNT($BD$2:$BD$7)-1),1),"") -> 20 | BU6: =IFERROR(MAX(0,MIN(100,MIN(IF(BM6,(BN6*0.2+BO6*0.325+BP6*0.325+BQ6*0.15),(BN6*0.2+BO6*0.15+BP6*0.15+BQ6*0.15+BR6*0.2+BS6*0.1+BT6*0.05))-(IF(AND(NOT(BM6),AW6<>"",AW6>2),20,0)),IF(AND(AN6<>"",AN6<0),40,999)))),"") -> 33 | BV6: =IFERROR(IF(BU6="","",IF((RANK(BU6,$BU$2:$BU$7,0)-1)/COUNT($BU$2:$BU$7)<0.2,"High",IF((RANK(BU6,$BU$2:$BU$7,0)-1)/COUNT($BU$2:$BU$7)<0.4,"Good",IF((RANK(BU6,$BU$2:$BU$7,0)-1)/COUNT($BU$2:$BU$7)<0.6,"Average",IF((RANK(BU6,$BU$2:$BU$7,0)-1)/COUNT($BU$2:$BU$7)<0.8,"Weak","Poor"))))),"") -> Poor
A7: ='Company Master'!A7 -> INE752E01010 | B7: ='Company Master'!C7 -> Power Grid Corp | C7: ='Company Master'!D7 -> Utilities | D7: =SUMPRODUCT(('Price History'!$A$2:$A$1561=A7)*('Price History'!$E$2:$E$1561=1)*'Price History'!$C$2:$C$1561) -> 1714.81 | E7: =D7-(SUMPRODUCT(('Price History'!$A$2:$A$1561=A7)*('Price History'!$E$2:$E$1561=2)*'Price History'!$C$2:$C$1561)) -> 4.82 | F7: =IFERROR(E7/(SUMPRODUCT(('Price History'!$A$2:$A$1561=A7)*('Price History'!$E$2:$E$1561=2)*'Price History'!$C$2:$C$1561)),"") -> 0.0028187299 | G7: ='Company Master'!E7 -> 300000 | H7: =IFERROR(D7/(INDEX('Fundamentals Raw'!$A:$AG,BH7,13)),'Company Master'!F7) -> 26.292702 | I7: =IFERROR(L7/M7*100,"") -> 62.592613 | J7: =_xlfn.MAXIFS('Price History'!$C$2:$C$1561,'Price History'!$A$2:$A$1561,A7,'Price History'!$E$2:$E$1561,"<=252") -> 1795.73 | K7: =_xlfn.MINIFS('Price History'!$C$2:$C$1561,'Price History'!$A$2:$A$1561,A7,'Price History'!$E$2:$E$1561,"<=252") -> 1489.3 | L7: =SUMPRODUCT(('Price History'!$A$2:$A$1561=A7)*('Price History'!$E$2:$E$1561=1)*'Price History'!$D$2:$D$1561) -> 997646 | M7: =AVERAGEIFS('Price History'!$D$2:$D$1561,'Price History'!$A$2:$A$1561,A7,'Price History'!$E$2:$E$1561,"<=30") -> 1593871.8 | N7: =IFERROR(AVERAGEIFS('Price History'!$C$2:$C$1561,'Price History'!$A$2:$A$1561,A7,'Price History'!$E$2:$E$1561,"<=3"),"") -> 1714.48 | O7: =IFERROR(AVERAGEIFS('Price History'!$C$2:$C$1561,'Price History'!$A$2:$A$1561,A7,'Price History'!$E$2:$E$1561,"<=8"),"") -> 1722.0475 | P7: =IFERROR(AVERAGEIFS('Price History'!$C$2:$C$1561,'Price History'!$A$2:$A$1561,A7,'Price History'!$E$2:$E$1561,"<=30"),"") -> 1738.9203 | Q7: =IFERROR(AVERAGEIFS('Price History'!$C$2:$C$1561,'Price History'!$A$2:$A$1561,A7,'Price History'!$E$2:$E$1561,"<=50"),"") -> 1746.2948 | R7: =IFERROR(AVERAGEIFS('Price History'!$C$2:$C$1561,'Price History'!$A$2:$A$1561,A7,'Price History'!$E$2:$E$1561,"<=100"),"") -> 1728.5496 | S7: =IFERROR(AVERAGEIFS('Price History'!$C$2:$C$1561,'Price History'!$A$2:$A$1561,A7,'Price History'!$E$2:$E$1561,"<=200"),"") -> 1670.4751 | T7: =IFERROR(100-100/(1+(AVERAGEIFS('Price History'!$G$2:$G$1561,'Price History'!$A$2:$A$1561,A7,'Price History'!$E$2:$E$1561,"<=14"))/(AVERAGEIFS('Price History'!$H$2:$H$1561,'Price History'!$A$2:$A$1561,A7,'Price History'!$E$2:$E$1561,"<=14"))),100) -> 44.347319 | U7: =IFERROR(ROUND(1+98*(RANK(BI7,$BI$2:$BI$7,1)-1)/(COUNT($BI$2:$BI$7)-1),0),"") -> 21 | V7: =IF(N7="","",D7>N7) -> TRUE | W7: =IF(O7="","",D7>O7) -> FALSE | X7: =IF(P7="","",D7>P7) -> FALSE | Y7: =IF(Q7="","",D7>Q7) -> FALSE | Z7: =IF(R7="","",D7>R7) -> FALSE | AA7: =IF(S7="","",D7>S7) -> TRUE | AB7: =IF(OR(N7="",O7=""),"",N7>O7) -> FALSE | AC7: =IF(OR(O7="",P7=""),"",O7>P7) -> FALSE | AD7: =IF(OR(P7="",R7=""),"",P7>R7) -> TRUE | AE7: =IF(OR(R7="",S7=""),"",R7>S7) -> TRUE | AF7: =IFERROR(AVERAGE(INDEX('Fundamentals Raw'!$A:$AG,BH7,3),INDEX('Fundamentals Raw'!$A:$AG,BH7,4),INDEX('Fundamentals Raw'!$A:$AG,BH7,5)),"") -> 15.843333 | AG7: =IFERROR(INDEX('Fundamentals Raw'!$A:$AG,BH7,5),"") -> 14.12 | AH7: =IFERROR((AG7-AF7)/ABS(AF7)*100,"") -> -10.877341 | AI7: =IF(AH7="","N/A",IF(ABS(AH7)<3,"Neutral",IF(AH7>0,"Improvement","Deterioration"))) -> Deterioration | AJ7: =IFERROR(AVERAGE(INDEX('Fundamentals Raw'!$A:$AG,BH7,7),INDEX('Fundamentals Raw'!$A:$AG,BH7,8),INDEX('Fundamentals Raw'!$A:$AG,BH7,9)),"") -> 16.13 | AK7: =IFERROR(INDEX('Fundamentals Raw'!$A:$AG,BH7,9),"") -> 16.73 | AL7: =IFERROR((AK7-AJ7)/ABS(AJ7)*100,"") -> 3.7197768 | AM7: =IF(AL7="","N/A",IF(ABS(AL7)<3,"Neutral",IF(AL7>0,"Improvement","Deterioration"))) -> Improvement | AN7: =IFERROR(AVERAGE(((INDEX('Fundamentals Raw'!$A:$AG,BH7,11)-INDEX('Fundamentals Raw'!$A:$AG,BH7,10))/ABS(INDEX('Fundamentals Raw'!$A:$AG,BH7,10))),((INDEX('Fundamentals Raw'!$A:$AG,BH7,12)-INDEX('Fundamentals Raw'!$A:$AG,BH7,11))/ABS(INDEX('Fundamentals Raw'!$A:$AG,BH7,11))),((INDEX('Fundamentals Raw'!$A:$AG,BH7,13)-INDEX('Fundamentals Raw'!$A:$AG,BH7,12))/ABS(INDEX('Fundamentals Raw'!$A:$AG,BH7,12))))*100,"") -> 12.439756 | AO7: =IFERROR((((INDEX('Fundamentals Raw'!$A:$AG,BH7,13)-INDEX('Fundamentals Raw'!$A:$AG,BH7,12))/ABS(INDEX('Fundamentals Raw'!$A:$AG,BH7,12))))*100,"") -> 14.844163 | AP7: =IFERROR((AO7-AN7)/ABS(AN7)*100,"") -> 19.328406 | AQ7: =IF(AP7="","N/A",IF(ABS(AP7)<3,"Neutral",IF(AP7>0,"Improvement","Deterioration"))) -> Improvement | AR7: =IFERROR(AVERAGE(((INDEX('Fundamentals Raw'!$A:$AG,BH7,15)-INDEX('Fundamentals Raw'!$A:$AG,BH7,14))/ABS(INDEX('Fundamentals Raw'!$A:$AG,BH7,14))),((INDEX('Fundamentals Raw'!$A:$AG,BH7,16)-INDEX('Fundamentals Raw'!$A:$AG,BH7,15))/ABS(INDEX('Fundamentals Raw'!$A:$AG,BH7,15))),((INDEX('Fundamentals Raw'!$A:$AG,BH7,17)-INDEX('Fundamentals Raw'!$A:$AG,BH7,16))/ABS(INDEX('Fundamentals Raw'!$A:$AG,BH7,16))))*100,"") -> 10.364991 | AS7: =IFERROR((((INDEX('Fundamentals Raw'!$A:$AG,BH7,17)-INDEX('Fundamentals Raw'!$A:$AG,BH7,16))/ABS(INDEX('Fundamentals Raw'!$A:$AG,BH7,16))))*100,"") -> 9.0317764 | AT7: =IFERROR((AS7-AR7)/ABS(AR7)*100,"") -> -12.862669 | AU7: =IF(AT7="","N/A",IF(ABS(AT7)<3,"Neutral",IF(AT7>0,"Improvement","Deterioration"))) -> Deterioration | AV7: =IFERROR(AVERAGE((INDEX('Fundamentals Raw'!$A:$AG,BH7,19)/INDEX('Fundamentals Raw'!$A:$AG,BH7,23)),(INDEX('Fundamentals Raw'!$A:$AG,BH7,20)/INDEX('Fundamentals Raw'!$A:$AG,BH7,24)),(INDEX('Fundamentals Raw'!$A:$AG,BH7,21)/INDEX('Fundamentals Raw'!$A:$AG,BH7,25))),"") -> 0.43600101 | AW7: =IFERROR((INDEX('Fundamentals Raw'!$A:$AG,BH7,21)/INDEX('Fundamentals Raw'!$A:$AG,BH7,25)),"") -> 0.36920278 | AX7: =IFERROR((AW7-AV7)/ABS(AV7)*100,"") -> -15.32066 | AY7: =IF(AX7="","N/A",IF(ABS(AX7)<3,"Neutral",IF(AX7>0,"Deterioration","Improvement"))) -> Improvement | AZ7: =IFERROR(AVERAGE((INDEX('Fundamentals Raw'!$A:$AG,BH7,15)/INDEX('Fundamentals Raw'!$A:$AG,BH7,27)),(INDEX('Fundamentals Raw'!$A:$AG,BH7,16)/INDEX('Fundamentals Raw'!$A:$AG,BH7,28)),(INDEX('Fundamentals Raw'!$A:$AG,BH7,17)/INDEX('Fundamentals Raw'!$A:$AG,BH7,29))),"") -> 1.2442792 | BA7: =IFERROR((INDEX('Fundamentals Raw'!$A:$AG,BH7,17)/INDEX('Fundamentals Raw'!$A:$AG,BH7,29)),"") -> 1.4743929 | BB7: =IFERROR((BA7-AZ7)/ABS(AZ7)*100,"") -> 18.493734 | BC7: =IF(BB7="","N/A",IF(ABS(BB7)<3,"Neutral",IF(BB7>0,"Improvement","Deterioration"))) -> Improvement | BD7: =IFERROR((INDEX('Fundamentals Raw'!$A:$AG,BH7,33))/(INDEX('Fundamentals Raw'!$A:$AG,BH7,29))*100,"") -> 9.9636048 | BE7: =IFERROR((D7/J7-1)*100,"") -> -4.5062454 | BF7: =IFERROR((D7/K7-1)*100,"") -> 15.142013 | BG7: =IFERROR(D7/K7,"") -> 1.1514201 | BH7: =IFERROR(MATCH(A7,'Fundamentals Raw'!$A:$A,0),"") -> 7 | BI7: =IFERROR(0.4*(D7/(SUMPRODUCT(('Price History'!$A$2:$A$1561=A7)*('Price History'!$E$2:$E$1561=64)*'Price History'!$C$2:$C$1561)))+0.2*(D7/(SUMPRODUCT(('Price History'!$A$2:$A$1561=A7)*('Price History'!$E$2:$E$1561=127)*'Price History'!$C$2:$C$1561)))+0.2*(D7/(SUMPRODUCT(('Price History'!$A$2:$A$1561=A7)*('Price History'!$E$2:$E$1561=190)*'Price History'!$C$2:$C$1561)))+0.2*(D7/(SUMPRODUCT(('Price History'!$A$2:$A$1561=A7)*('Price History'!$E$2:$E$1561=253)*'Price History'!$C$2:$C$1561))),"") -> 1.0509667 | BJ7: =IFERROR(IF(U7<60,"Red",IF(U7<80,"Amber","Green")),"") -> Red | BK7: =IFERROR((S7-(AVERAGEIFS('Price History'!$C$2:$C$1561,'Price History'!$A$2:$A$1561,A7,'Price History'!$E$2:$E$1561,">=21",'Price History'!$E$2:$E$1561,"<=220")))/ABS(AVERAGEIFS('Price History'!$C$2:$C$1561,'Price History'!$A$2:$A$1561,A7,'Price History'!$E$2:$E$1561,">=21",'Price History'!$E$2:$E$1561,"<=220"))*100,"") -> 1.0227397 | BL7: =IFERROR(BK7>0,"") -> TRUE | BM7: =OR(C7="Banks",C7="Finance (including NBFCs)",C7="Housing Finance",C7="Microfinance Institutions",C7="Financial Institutions",C7="Asset Management Cos.",C7="Capital Markets",C7="Investment Companies",C7="General Insurance",C7="Life Insurance",C7="Other Financial Services") -> FALSE | BN7: =IFERROR(ROUND(100*(RANK(AF7,$AF$2:$AF$7,1)-1)/(COUNT($AF$2:$AF$7)-1),1),"") -> 20 | BO7: =IFERROR(ROUND(100*(RANK(AJ7,$AJ$2:$AJ$7,1)-1)/(COUNT($AJ$2:$AJ$7)-1),1),"") -> 20 | BP7: =IFERROR(ROUND(100*(RANK(AN7,$AN$2:$AN$7,1)-1)/(COUNT($AN$2:$AN$7)-1),1),"") -> 80 | BQ7: =IFERROR(ROUND(100*(RANK(AR7,$AR$2:$AR$7,1)-1)/(COUNT($AR$2:$AR$7)-1),1),"") -> 100 | BR7: =IFERROR(ROUND(100*(COUNT($AW$2:$AW$7)-RANK(AW7,$AW$2:$AW$7,1))/(COUNT($AW$2:$AW$7)-1),1),"") -> 80 | BS7: =IFERROR(ROUND(100*(RANK(BA7,$BA$2:$BA$7,1)-1)/(COUNT($BA$2:$BA$7)-1),1),"") -> 100 | BT7: =IFERROR(ROUND(100*(RANK(BD7,$BD$2:$BD$7,1)-1)/(COUNT($BD$2:$BD$7)-1),1),"") -> 100 | BU7: =IFERROR(MAX(0,MIN(100,MIN(IF(BM7,(BN7*0.2+BO7*0.325+BP7*0.325+BQ7*0.15),(BN7*0.2+BO7*0.15+BP7*0.15+BQ7*0.15+BR7*0.2+BS7*0.1+BT7*0.05))-(IF(AND(NOT(BM7),AW7<>"",AW7>2),20,0)),IF(AND(AN7<>"",AN7<0),40,999)))),"") -> 65 | BV7: =IFERROR(IF(BU7="","",IF((RANK(BU7,$BU$2:$BU$7,0)-1)/COUNT($BU$2:$BU$7)<0.2,"High",IF((RANK(BU7,$BU$2:$BU$7,0)-1)/COUNT($BU$2:$BU$7)<0.4,"Good",IF((RANK(BU7,$BU$2:$BU$7,0)-1)/COUNT($BU$2:$BU$7)<0.6,"Average",IF((RANK(BU7,$BU$2:$BU$7,0)-1)/COUNT($BU$2:$BU$7)<0.8,"Weak","Poor"))))),"") -> High

Sheet Company Master
A1: ISIN | B1: Symbol | C1: Name | D1: Sector | E1: MarketCap (₹ Cr) | F1: PE | G1: PB
A2: INE002A01018 | B2: RELIANCE | C2: Reliance Industries | D2: Energy | E2: 1750000 | F2: 24.1 | G2: 2.3
A3: INE467B01029 | B3: TCS | C3: Tata Consultancy Services | D3: IT | E3: 1420000 | F3: 27.8 | G3: 12.1
A4: INE040A01034 | B4: HDFCBANK | C4: HDFC Bank | D4: Banks | E4: 1280000 | F4: 18.4 | G4: 2.6
A5: INE154A01025 | B5: ITC | C5: ITC Ltd | D5: FMCG | E5: 540000 | F5: 22.9 | G5: 6.2
A6: INE075A01022 | B6: WIPRO | C6: Wipro Ltd | D6: IT | E6: 260000 | F6: 20.3 | G6: 3.4
A7: INE752E01010 | B7: POWERGRID | C7: Power Grid Corp | D7: Utilities | E7: 300000 | F7: 15.2 | G7: 3.1

Sheet Fundamentals Raw
A1: ISIN | B1: ROE % FY23 | C1: ROE % FY24 | D1: ROE % FY25 | E1: ROE % FY26 | F1: ROCE % FY23 | G1: ROCE % FY24 | H1: ROCE % FY25 | I1: ROCE % FY26 | J1: EPS FY23 | K1: EPS FY24 | L1: EPS FY25 | M1: EPS FY26 | N1: Sales FY23 | O1: Sales FY24 | P1: Sales FY25 | Q1: Sales FY26 | R1: TotalDebt FY23 | S1: TotalDebt FY24 | T1: TotalDebt FY25 | U1: TotalDebt FY26 | V1: Equity FY23 | W1: Equity FY24 | X1: Equity FY25 | Y1: Equity FY26 | Z1: FixedAssets FY23 | AA1: FixedAssets FY24 | AB1: FixedAssets FY25 | AC1: FixedAssets FY26 | AD1: CWIP FY23 | AE1: CWIP FY24 | AF1: CWIP FY25 | AG1: CWIP FY26
A2: INE002A01018 | B2: 13.79 | C2: 12.21 | D2: 17.59 | E2: 18.46 | F2: 18.06 | G2: 17.9 | H2: 14.93 | I2: 17.22 | J2: 43.1 | K2: 47.43 | L2: 53.63 | M2: 59.55 | N2: 212400 | O2: 228859 | P2: 242710 | Q2: 273728 | R2: 61923 | S2: 50265 | T2: 78542 | U2: 86135 | V2: 111197 | W2: 120259 | X2: 134746 | Y2: 146178 | Z2: 223071 | AA2: 221706 | AB2: 220253 | AC2: 242856 | AD2: 11991 | AE2: 14886 | AF2: 6039 | AG2: 15582
A3: INE467B01029 | B3: 16.62 | C3: 17.09 | D3: 17.83 | E3: 13.83 | F3: 14.27 | G3: 16.22 | H3: 16.28 | I3: 15.89 | J3: 45.45 | K3: 48.98 | L3: 52.27 | M3: 58.94 | N3: 221896 | O3: 237003 | P3: 262772 | Q3: 296257 | R3: 32653 | S3: 34744 | T3: 81140 | U3: 46599 | V3: 112147 | W3: 122424 | X3: 136185 | Y3: 151741 | Z3: 206678 | AA3: 223548 | AB3: 204652 | AC3: 288584 | AD3: 5453 | AE3: 21222 | AF3: 13211 | AG3: 27540
A4: INE040A01034 | B4: 15.17 | C4: 15.2 | D4: 15.38 | E4: 17.45 | F4: 16.75 | G4: 19.99 | H4: 16.29 | I4: 15.6 | J4: 44.62 | K4: 50.86 | L4: 57.43 | M4: 64.44 | N4: 217035 | O4: 240207 | P4: 266677 | Q4: 282922 | R4: 34383 | S4: 49608 | T4: 79803 | U4: 68347 | V4: 112382 | W4: 122849 | X4: 133350 | Y4: 149757 | Z4: 207099 | AA4: 251645 | AB4: 219042 | AC4: 292598 | AD4: 13443 | AE4: 5981 | AF4: 21397 | AG4: 16029
A5: INE154A01025 | B5: 14.11 | C5: 18.1 | D5: 18.65 | E5: 18.13 | F5: 15.07 | G5: 18.67 | H5: 14.35 | I5: 16.85 | J5: 45.5 | K5: 48.47 | L5: 55.16 | M5: 62.11 | N5: 227261 | O5: 251968 | P5: 285815 | Q5: 304546 | R5: 62307 | S5: 50534 | T5: 73057 | U5: 61462 | V5: 110269 | W5: 122613 | X5: 132541 | Y5: 146365 | Z5: 159783 | AA5: 279858 | AB5: 194674 | AC5: 287570 | AD5: 7011 | AE5: 12855 | AF5: 5227 | AG5: 25822
A6: INE075A01022 | B6: 17.84 | C6: 14.7 | D6: 12.57 | E6: 18.46 | F6: 15.87 | G6: 15.38 | H6: 18.01 | I6: 14.58 | J6: 44.16 | K6: 47.36 | L6: 53.8 | M6: 60.71 | N6: 215389 | O6: 230397 | P6: 260909 | Q6: 286430 | R6: 65856 | S6: 35082 | T6: 37972 | U6: 54872 | V6: 110116 | W6: 121775 | X6: 132911 | Y6: 147338 | Z6: 166978 | AA6: 244428 | AB6: 266401 | AC6: 248175 | AD6: 9192 | AE6: 17229 | AF6: 25266 | AG6: 14236
